<?xml version="1.0" ?>
<!-- =================================================================================== -->
<!-- |    This document was autogenerated by xacro from Strandbeest.xacro              | -->
<!-- |    EDITING THIS FILE BY HAND IS NOT RECOMMENDED                                 | -->
<!-- =================================================================================== -->
<robot name="Strandbeest" xmlns="http://drake.mit.edu" xmlns:xacro="http://ros.org/wiki/xacro" xmlns:xsi="http://www.w3.org/2001/XMLSchema-instance" xsi:schemaLocation="http://drake.mit.edu ../../doc/drakeURDF.xsd">
  <material name="#FF9619">
    <color rgba="1.0 0.5882353 0.098039225 1"/>
  </material>
  <material name="#FE6860">
    <color rgba="0.9960785 0.40784317 0.37647063 1"/>
  </material>
  <material name="#D2588C">
    <color rgba="0.8235295 0.34509805 0.54901963 1"/>
  </material>
  <material name="#8C5C99">
    <color rgba="0.54901963 0.36078432 0.6 1"/>
  </material>
  <material name="#4A5782">
    <color rgba="0.2901961 0.34117648 0.50980395 1"/>
  </material>
  <material name="#2F4858">
    <color rgba="0.18431373 0.28235295 0.34509805 1"/>
  </material>
  <link name="crossbar">
    <inertial>
      <origin rpy="1.57079632679 0 0" xyz="0 0 0"/>
      <mass value="1"/>
      <inertia ixx="1" ixy="0" ixz="0" iyy="1" iyz="0" izz="1"/>
    </inertial>
    <visual>
      <origin rpy="1.57079632679 0 0" xyz="0 0 0"/>
      <geometry>
        <cylinder length="0.2" radius="0.01"/>
      </geometry>
      <material name="orange">
        <color rgba="1 .6392 .0980 1"/>
      </material>
    </visual>
  </link>
  <link name="crank_axle">
    <inertial>
      <origin rpy="1.57079632679 0 0" xyz="0 0 0"/>
      <mass value="1"/>
      <inertia ixx="1" ixy="0" ixz="0" iyy="1" iyz="0" izz="1"/>
    </inertial>
    <visual>
      <origin rpy="1.57079632679 0 0" xyz="0 0 0"/>
      <geometry>
        <cylinder length="0.2" radius="0.02"/>
      </geometry>
      <material name="orange"/>
    </visual>
  </link>
  <joint name="joint_crossbar_crank" type="continuous">
    <axis xyz="0 1 0"/>
    <parent link="crossbar"/>
    <child link="crank_axle"/>
    <origin rpy="0 0 0" xyz="0 0 0.078"/>
  </joint>

    <link name="pair01_bar_m">
    <inertial>
      <origin rpy="0 0 0" xyz="0 0 0.075"/>
      <mass value="1"/>
      <inertia ixx="1" ixy="0" ixz="0" iyy="1" iyz="0" izz="1"/>
    </inertial>
    <visual>
      <origin rpy="0 0 0" xyz="0 0 0.075"/>
      <geometry>
        <cylinder length="0.15" radius="0.01"/>
      </geometry>
      <material name="#2F4858"/>
    </visual>
  </link>

    <joint name="pair01_joint_crank_axle_m" type="fixed">
    <axis xyz="0 1 0"/>
    <parent link="crank_axle"/>
    <child link="pair01_bar_m"/>
    <origin rpy="0 0 0" xyz="0 -0.1 0"/>
  </joint>

  <link name="pair01_leg1_bar_j">
    <inertial>
      <origin rpy="0 0 0" xyz="0 0 0.25"/>
      <mass value="1"/>
      <inertia ixx="1" ixy="0" ixz="0" iyy="1" iyz="0" izz="1"/>
    </inertial>
    <visual>
      <origin rpy="0 0 0" xyz="0 0 0.25"/>
      <geometry>
        <cylinder length="0.50" radius="0.01"/>
      </geometry>
      <material name="#2F4858"/>
    </visual>
  </link>

    <joint name="pair01_leg1_joint_m_j" type="continuous">
    <axis xyz="0 1 0"/>
    <parent link="pair01_bar_m"/>
    <child link="pair01_leg1_bar_j"/>
    <origin rpy="0 0 0" xyz="0 0 0.15"/>
  </joint>

   <link name="pair01_bar_l">
    <inertial>
      <origin rpy="0 0 0" xyz="0 0 0.039"/>
      <mass value="1"/>
      <inertia ixx="1" ixy="0" ixz="0" iyy="1" iyz="0" izz="1"/>
    </inertial>
    <visual>
      <origin rpy="0 0 0" xyz="0 0 0.039"/>
      <geometry>
        <cylinder length="0.078" radius="0.01"/>
      </geometry>
      <material name="#2F4858"/>
    </visual>
  </link>
  <link name="pair01_bar_a">
    <inertial>
      <origin rpy="0 0 0" xyz="0 0 0"/>
      <mass value="1"/>
      <inertia ixx="1" ixy="0" ixz="0" iyy="1" iyz="0" izz="1"/>
    </inertial>
    <visual>
      <origin rpy="0 0 0" xyz="0 0 0"/>
      <geometry>
        <cylinder length="0.76" radius="0.01"/>
      </geometry>
      <material name="#2F4858"/>
    </visual>
  </link>
  <joint name="pair01_joint_l_a" type="fixed">
    <axis xyz="0 1 0"/>
    <parent link="pair01_bar_l"/>
    <child link="pair01_bar_a"/>
    <origin rpy="0 -1.57079632679 0" xyz="0 0 0"/>
  </joint>

    <joint name="pair01_joint_crossbar_l" type="fixed">
    <axis xyz="0 1 0"/>
    <parent link="crossbar"/>
    <child link="pair01_bar_l"/>
    <origin rpy="0 0 0" xyz="0 -0.1 0"/>
  </joint>
    <!-- <loop_joint name="pair01_loop_crank_l" type="continuous">
    <axis xyz="0 1 0"/>
    <link1 link="crank_axle" rpy="0 0 0" xyz="0 -0.1 0"/>
    <link2 link="pair01_bar_l" rpy="0 0 0" xyz="0 0 0.078"/>
  </loop_joint> -->

  <!-- <link name="pair01_leg1_bars_b_d_e">
    <inertial>
      <origin rpy="0 0 0" xyz="0 0 0"/>
      <mass value="1"/>
      <inertia ixx="1" ixy="0" ixz="0" iyy="1" iyz="0" izz="1"/>
    </inertial>
    <visual>
      <origin rpy="0 0 0" xyz="0 0 0.279"/>
      <geometry>
        <cylinder length="0.558" radius="0.01"/>
      </geometry>
      <material name="#2F4858"/>
    </visual>
    <visual>
      <origin rpy="0 -2.3056 0" xyz="-0.1488 0 0.4236"/>
      <geometry>
        <cylinder length="0.401" radius="0.01"/>
      </geometry>
      <material name="#2F4858"/>
    </visual>
    <visual>
      <origin rpy="0 -0.8 0" xyz="-0.1489 0 0.1446"/>
      <geometry>
        <cylinder length="0.415" radius="0.01"/>
      </geometry>
      <material name="#2F4858"/>
    </visual>
  </link> -->

   <link name="pair01_leg1_bars_b">
    <inertial>
      <origin rpy="0 0 0" xyz="0 0 0"/>
      <mass value="1"/>
      <inertia ixx="1" ixy="0" ixz="0" iyy="1" iyz="0" izz="1"/>
    </inertial>
    <visual>
      <origin rpy="0 0 0" xyz="0 0 0.2075"/>
      <geometry>
        <cylinder length="0.415" radius="0.01"/>
      </geometry>
      <material name="#2F4858"/>
    </visual>
  </link>

  <!-- <joint name="pair01_leg1_joint_j_e" type="revolute">
    <axis xyz="0 1 0"/>
    <parent link="pair01_leg1_bar_j"/>
    <child link="pair01_leg1_bars_b_d_e"/>
    <origin rpy="0 0 0" xyz="0 0 0.50"/>
    <limit effort="0" lower="-1.9" upper="-1.0" velocity="1000"/>
  </joint> -->

  <joint name="pair01_leg1_joint_b_a" type="revolute">
    <origin xyz="0.0 0.0 0.38" rpy="0.0 0.0 0.0"/>
    <parent link="pair01_bar_a"/>
    <child link="pair01_leg1_bars_b"/>
    <axis xyz="0.0 1 0.0"/>
    <!-- <limit lower="0.0" upper="0.0" effort="0.0" velocity="0.0"/> -->
  </joint>
<!-- 
    <loop_joint name="pair01_leg1_loop_b_a" type="continuous">
    <axis xyz="0 1 0"/>
    <link1 link="pair01_leg1_bars_b_d_e" rpy="0 0 0" xyz="-0.2978 0 0.2892"/>
    <link2 link="pair01_bar_a" rpy="0 0 0" xyz="0 0 0.38"/>
  </loop_joint> -->

    <loop_joint name="pair01_leg1_loop_b_j" type="continuous">
    <axis xyz="0 1 0"/>
    <link1 link="pair01_leg1_bars_b" rpy="0 0 0" xyz="0 0 0.415"/>
    <link2 link="pair01_leg1_bar_j" rpy="0 0 0" xyz="0 0 0.50"/>
  </loop_joint> 

    <link name="pair01_leg1_bar_k">
    <inertial>
      <origin rpy="0 0 0" xyz="0 0 0.3095"/>
      <mass value="1"/>
      <inertia ixx="1" ixy="0" ixz="0" iyy="1" iyz="0" izz="1"/>
    </inertial>
    <visual>
      <origin rpy="0 0 0" xyz="0 0 0.3095"/>
      <geometry>
        <cylinder length="0.619" radius="0.01"/>
      </geometry>
      <material name="#2F4858"/>
    </visual>
  </link>
  <joint name="pair01_leg1_joint_m_k" type="revolute">
    <axis xyz="0 1 0"/>
    <parent link="pair01_bar_m"/>
    <child link="pair01_leg1_bar_k"/>
    <origin rpy="0 0 0" xyz="0 0 0.15"/>
    <!-- <limit effort="0" lower="-1.8" upper="-1.1" velocity="1000"/> -->
  </joint>

   <link name="pair01_leg1_bar_c">
    <inertial>
      <origin rpy="0 0 0" xyz="0 0 0.1965"/>
      <mass value="1"/>
      <inertia ixx="1" ixy="0" ixz="0" iyy="1" iyz="0" izz="1"/>
    </inertial>
    <visual>
      <origin rpy="0 0 0" xyz="0 0 0.1965"/>
      <geometry>
        <cylinder length="0.393" radius="0.01"/>
      </geometry>
      <material name="#2F4858"/>
    </visual>
  </link>
  <joint name="pair01_leg1_joint_a_c" type="revolute">
    <axis xyz="0 1 0"/>
    <parent link="pair01_bar_a"/>
    <child link="pair01_leg1_bar_c"/>
    <origin rpy="0 0 0" xyz="0 0 0.38"/>
    <!-- <limit effort="0" lower="1.57079632679" upper="3.14159265359" velocity="1000"/> -->
  </joint>

  <loop_joint name="pair01_leg1_loop_c_k" type="continuous">
    <axis xyz="0 1 0"/>
    <link1 link="pair01_leg1_bar_c" rpy="0 0 0" xyz="0 0 0.393"/>
    <link2 link="pair01_leg1_bar_k" rpy="0 0 0" xyz="0 0 0.619"/>
  </loop_joint> 

  

</robot>
